<?xml version="1.0" ?>
<robot name="partnet_297684bcd05347cd86d53ab0fe94e911">
	<link name="base"/>
	<link name="link_0">
		<visual name="cabinet_door_surface-51">
			<origin xyz="-0.6228630061007897 -0.3372400104999542 -0.4255421443805475"/>
			<geometry>
				<mesh filename="textured_objs/original-83.obj"/>
			</geometry>
		</visual>
		<visual name="cabinet_door_surface-51">
			<origin xyz="-0.6228630061007897 -0.3372400104999542 -0.4255421443805475"/>
			<geometry>
				<mesh filename="textured_objs/original-79.obj"/>
			</geometry>
		</visual>
		<visual name="cabinet_door_surface-51">
			<origin xyz="-0.6228630061007897 -0.3372400104999542 -0.4255421443805475"/>
			<geometry>
				<mesh filename="textured_objs/original-77.obj"/>
			</geometry>
		</visual>
		<visual name="cabinet_door_surface-51">
			<origin xyz="-0.6228630061007897 -0.3372400104999542 -0.4255421443805475"/>
			<geometry>
				<mesh filename="textured_objs/original-73.obj"/>
			</geometry>
		</visual>
		<visual name="cabinet_door_surface-51">
			<origin xyz="-0.6228630061007897 -0.3372400104999542 -0.4255421443805475"/>
			<geometry>
				<mesh filename="textured_objs/original-74.obj"/>
			</geometry>
		</visual>
		<visual name="cabinet_door_surface-51">
			<origin xyz="-0.6228630061007897 -0.3372400104999542 -0.4255421443805475"/>
			<geometry>
				<mesh filename="textured_objs/original-80.obj"/>
			</geometry>
		</visual>
		<visual name="cabinet_door_surface-51">
			<origin xyz="-0.6228630061007897 -0.3372400104999542 -0.4255421443805475"/>
			<geometry>
				<mesh filename="textured_objs/original-75.obj"/>
			</geometry>
		</visual>
		<visual name="cabinet_door_surface-51">
			<origin xyz="-0.6228630061007897 -0.3372400104999542 -0.4255421443805475"/>
			<geometry>
				<mesh filename="textured_objs/original-78.obj"/>
			</geometry>
		</visual>
		<visual name="cabinet_door_surface-51">
			<origin xyz="-0.6228630061007897 -0.3372400104999542 -0.4255421443805475"/>
			<geometry>
				<mesh filename="textured_objs/original-76.obj"/>
			</geometry>
		</visual>
		<visual name="cabinet_door_surface-51">
			<origin xyz="-0.6228630061007897 -0.3372400104999542 -0.4255421443805475"/>
			<geometry>
				<mesh filename="textured_objs/original-82.obj"/>
			</geometry>
		</visual>
		<visual name="handle-52">
			<origin xyz="-0.6228630061007897 -0.3372400104999542 -0.4255421443805475"/>
			<geometry>
				<mesh filename="textured_objs/original-86.obj"/>
			</geometry>
		</visual>
		<visual name="handle-52">
			<origin xyz="-0.6228630061007897 -0.3372400104999542 -0.4255421443805475"/>
			<geometry>
				<mesh filename="textured_objs/original-85.obj"/>
			</geometry>
		</visual>
		<visual name="handle-52">
			<origin xyz="-0.6228630061007897 -0.3372400104999542 -0.4255421443805475"/>
			<geometry>
				<mesh filename="textured_objs/original-87.obj"/>
			</geometry>
		</visual>
		<collision>
			<origin xyz="-0.6228630061007897 -0.3372400104999542 -0.4255421443805475"/>
			<geometry>
				<mesh filename="textured_objs/original-83.obj"/>
			</geometry>
		</collision>
		<collision>
			<origin xyz="-0.6228630061007897 -0.3372400104999542 -0.4255421443805475"/>
			<geometry>
				<mesh filename="textured_objs/original-79.obj"/>
			</geometry>
		</collision>
		<collision>
			<origin xyz="-0.6228630061007897 -0.3372400104999542 -0.4255421443805475"/>
			<geometry>
				<mesh filename="textured_objs/original-77.obj"/>
			</geometry>
		</collision>
		<collision>
			<origin xyz="-0.6228630061007897 -0.3372400104999542 -0.4255421443805475"/>
			<geometry>
				<mesh filename="textured_objs/original-73.obj"/>
			</geometry>
		</collision>
		<collision>
			<origin xyz="-0.6228630061007897 -0.3372400104999542 -0.4255421443805475"/>
			<geometry>
				<mesh filename="textured_objs/original-74.obj"/>
			</geometry>
		</collision>
		<collision>
			<origin xyz="-0.6228630061007897 -0.3372400104999542 -0.4255421443805475"/>
			<geometry>
				<mesh filename="textured_objs/original-80.obj"/>
			</geometry>
		</collision>
		<collision>
			<origin xyz="-0.6228630061007897 -0.3372400104999542 -0.4255421443805475"/>
			<geometry>
				<mesh filename="textured_objs/original-75.obj"/>
			</geometry>
		</collision>
		<collision>
			<origin xyz="-0.6228630061007897 -0.3372400104999542 -0.4255421443805475"/>
			<geometry>
				<mesh filename="textured_objs/original-78.obj"/>
			</geometry>
		</collision>
		<collision>
			<origin xyz="-0.6228630061007897 -0.3372400104999542 -0.4255421443805475"/>
			<geometry>
				<mesh filename="textured_objs/original-76.obj"/>
			</geometry>
		</collision>
		<collision>
			<origin xyz="-0.6228630061007897 -0.3372400104999542 -0.4255421443805475"/>
			<geometry>
				<mesh filename="textured_objs/original-82.obj"/>
			</geometry>
		</collision>
		<collision>
			<origin xyz="-0.6228630061007897 -0.3372400104999542 -0.4255421443805475"/>
			<geometry>
				<mesh filename="textured_objs/original-86.obj"/>
			</geometry>
		</collision>
		<collision>
			<origin xyz="-0.6228630061007897 -0.3372400104999542 -0.4255421443805475"/>
			<geometry>
				<mesh filename="textured_objs/original-85.obj"/>
			</geometry>
		</collision>
		<collision>
			<origin xyz="-0.6228630061007897 -0.3372400104999542 -0.4255421443805475"/>
			<geometry>
				<mesh filename="textured_objs/original-87.obj"/>
			</geometry>
		</collision>
	</link>
	<joint name="joint_0" type="revolute">
		<origin xyz="0.6228630061007897 0.3372400104999542 0.4255421443805475"/>
		<axis xyz="0 1 0"/>
		<child link="link_0"/>
		<parent link="link_3"/>
		<limit lower="0.0" upper="1.7530087007031048"/>
	</joint>
	<link name="link_1">
		<visual name="cabinet_door_surface-48">
			<origin xyz="0.6287622190413499 0.4642939865589142 -0.4258897795226454"/>
			<geometry>
				<mesh filename="textured_objs/original-61.obj"/>
			</geometry>
		</visual>
		<visual name="cabinet_door_surface-48">
			<origin xyz="0.6287622190413499 0.4642939865589142 -0.4258897795226454"/>
			<geometry>
				<mesh filename="textured_objs/original-57.obj"/>
			</geometry>
		</visual>
		<visual name="cabinet_door_surface-48">
			<origin xyz="0.6287622190413499 0.4642939865589142 -0.4258897795226454"/>
			<geometry>
				<mesh filename="textured_objs/original-64.obj"/>
			</geometry>
		</visual>
		<visual name="cabinet_door_surface-48">
			<origin xyz="0.6287622190413499 0.4642939865589142 -0.4258897795226454"/>
			<geometry>
				<mesh filename="textured_objs/original-62.obj"/>
			</geometry>
		</visual>
		<visual name="cabinet_door_surface-48">
			<origin xyz="0.6287622190413499 0.4642939865589142 -0.4258897795226454"/>
			<geometry>
				<mesh filename="textured_objs/original-67.obj"/>
			</geometry>
		</visual>
		<visual name="cabinet_door_surface-48">
			<origin xyz="0.6287622190413499 0.4642939865589142 -0.4258897795226454"/>
			<geometry>
				<mesh filename="textured_objs/original-60.obj"/>
			</geometry>
		</visual>
		<visual name="cabinet_door_surface-48">
			<origin xyz="0.6287622190413499 0.4642939865589142 -0.4258897795226454"/>
			<geometry>
				<mesh filename="textured_objs/original-59.obj"/>
			</geometry>
		</visual>
		<visual name="cabinet_door_surface-48">
			<origin xyz="0.6287622190413499 0.4642939865589142 -0.4258897795226454"/>
			<geometry>
				<mesh filename="textured_objs/original-63.obj"/>
			</geometry>
		</visual>
		<visual name="cabinet_door_surface-48">
			<origin xyz="0.6287622190413499 0.4642939865589142 -0.4258897795226454"/>
			<geometry>
				<mesh filename="textured_objs/original-58.obj"/>
			</geometry>
		</visual>
		<visual name="cabinet_door_surface-48">
			<origin xyz="0.6287622190413499 0.4642939865589142 -0.4258897795226454"/>
			<geometry>
				<mesh filename="textured_objs/original-66.obj"/>
			</geometry>
		</visual>
		<visual name="handle-49">
			<origin xyz="0.6287622190413499 0.4642939865589142 -0.4258897795226454"/>
			<geometry>
				<mesh filename="textured_objs/original-69.obj"/>
			</geometry>
		</visual>
		<visual name="handle-49">
			<origin xyz="0.6287622190413499 0.4642939865589142 -0.4258897795226454"/>
			<geometry>
				<mesh filename="textured_objs/original-70.obj"/>
			</geometry>
		</visual>
		<visual name="handle-49">
			<origin xyz="0.6287622190413499 0.4642939865589142 -0.4258897795226454"/>
			<geometry>
				<mesh filename="textured_objs/original-71.obj"/>
			</geometry>
		</visual>
		<collision>
			<origin xyz="0.6287622190413499 0.4642939865589142 -0.4258897795226454"/>
			<geometry>
				<mesh filename="textured_objs/original-61.obj"/>
			</geometry>
		</collision>
		<collision>
			<origin xyz="0.6287622190413499 0.4642939865589142 -0.4258897795226454"/>
			<geometry>
				<mesh filename="textured_objs/original-57.obj"/>
			</geometry>
		</collision>
		<collision>
			<origin xyz="0.6287622190413499 0.4642939865589142 -0.4258897795226454"/>
			<geometry>
				<mesh filename="textured_objs/original-64.obj"/>
			</geometry>
		</collision>
		<collision>
			<origin xyz="0.6287622190413499 0.4642939865589142 -0.4258897795226454"/>
			<geometry>
				<mesh filename="textured_objs/original-62.obj"/>
			</geometry>
		</collision>
		<collision>
			<origin xyz="0.6287622190413499 0.4642939865589142 -0.4258897795226454"/>
			<geometry>
				<mesh filename="textured_objs/original-67.obj"/>
			</geometry>
		</collision>
		<collision>
			<origin xyz="0.6287622190413499 0.4642939865589142 -0.4258897795226454"/>
			<geometry>
				<mesh filename="textured_objs/original-60.obj"/>
			</geometry>
		</collision>
		<collision>
			<origin xyz="0.6287622190413499 0.4642939865589142 -0.4258897795226454"/>
			<geometry>
				<mesh filename="textured_objs/original-59.obj"/>
			</geometry>
		</collision>
		<collision>
			<origin xyz="0.6287622190413499 0.4642939865589142 -0.4258897795226454"/>
			<geometry>
				<mesh filename="textured_objs/original-63.obj"/>
			</geometry>
		</collision>
		<collision>
			<origin xyz="0.6287622190413499 0.4642939865589142 -0.4258897795226454"/>
			<geometry>
				<mesh filename="textured_objs/original-58.obj"/>
			</geometry>
		</collision>
		<collision>
			<origin xyz="0.6287622190413499 0.4642939865589142 -0.4258897795226454"/>
			<geometry>
				<mesh filename="textured_objs/original-66.obj"/>
			</geometry>
		</collision>
		<collision>
			<origin xyz="0.6287622190413499 0.4642939865589142 -0.4258897795226454"/>
			<geometry>
				<mesh filename="textured_objs/original-69.obj"/>
			</geometry>
		</collision>
		<collision>
			<origin xyz="0.6287622190413499 0.4642939865589142 -0.4258897795226454"/>
			<geometry>
				<mesh filename="textured_objs/original-70.obj"/>
			</geometry>
		</collision>
		<collision>
			<origin xyz="0.6287622190413499 0.4642939865589142 -0.4258897795226454"/>
			<geometry>
				<mesh filename="textured_objs/original-71.obj"/>
			</geometry>
		</collision>
	</link>
	<joint name="joint_1" type="revolute">
		<origin xyz="-0.6287622190413499 -0.4642939865589142 0.4258897795226454"/>
		<axis xyz="0 -1 0"/>
		<child link="link_1"/>
		<parent link="link_3"/>
		<limit lower="0.0" upper="1.7453292519943295"/>
	</joint>
	<link name="link_2">
		<visual name="drawer_front-53">
			<origin xyz="0.01855345890418502 -0.4566991883338948 0.41623198986053467"/>
			<geometry>
				<mesh filename="textured_objs/original-29.obj"/>
			</geometry>
		</visual>
		<visual name="drawer_front-53">
			<origin xyz="0.01855345890418502 -0.4566991883338948 0.41623198986053467"/>
			<geometry>
				<mesh filename="textured_objs/original-41.obj"/>
			</geometry>
		</visual>
		<visual name="drawer_front-53">
			<origin xyz="0.01855345890418502 -0.4566991883338948 0.41623198986053467"/>
			<geometry>
				<mesh filename="textured_objs/original-38.obj"/>
			</geometry>
		</visual>
		<visual name="drawer_front-53">
			<origin xyz="0.01855345890418502 -0.4566991883338948 0.41623198986053467"/>
			<geometry>
				<mesh filename="textured_objs/original-37.obj"/>
			</geometry>
		</visual>
		<visual name="drawer_front-53">
			<origin xyz="0.01855345890418502 -0.4566991883338948 0.41623198986053467"/>
			<geometry>
				<mesh filename="textured_objs/original-47.obj"/>
			</geometry>
		</visual>
		<visual name="drawer_front-53">
			<origin xyz="0.01855345890418502 -0.4566991883338948 0.41623198986053467"/>
			<geometry>
				<mesh filename="textured_objs/original-40.obj"/>
			</geometry>
		</visual>
		<visual name="drawer_front-53">
			<origin xyz="0.01855345890418502 -0.4566991883338948 0.41623198986053467"/>
			<geometry>
				<mesh filename="textured_objs/original-43.obj"/>
			</geometry>
		</visual>
		<visual name="drawer_front-53">
			<origin xyz="0.01855345890418502 -0.4566991883338948 0.41623198986053467"/>
			<geometry>
				<mesh filename="textured_objs/original-42.obj"/>
			</geometry>
		</visual>
		<visual name="drawer_front-53">
			<origin xyz="0.01855345890418502 -0.4566991883338948 0.41623198986053467"/>
			<geometry>
				<mesh filename="textured_objs/original-39.obj"/>
			</geometry>
		</visual>
		<visual name="drawer_front-53">
			<origin xyz="0.01855345890418502 -0.4566991883338948 0.41623198986053467"/>
			<geometry>
				<mesh filename="textured_objs/original-44.obj"/>
			</geometry>
		</visual>
		<visual name="drawer_front-53">
			<origin xyz="0.01855345890418502 -0.4566991883338948 0.41623198986053467"/>
			<geometry>
				<mesh filename="textured_objs/original-46.obj"/>
			</geometry>
		</visual>
		<visual name="drawer_side-54">
			<origin xyz="0.01855345890418502 -0.4566991883338948 0.41623198986053467"/>
			<geometry>
				<mesh filename="textured_objs/original-28.obj"/>
			</geometry>
		</visual>
		<visual name="drawer_side-54">
			<origin xyz="0.01855345890418502 -0.4566991883338948 0.41623198986053467"/>
			<geometry>
				<mesh filename="textured_objs/original-35.obj"/>
			</geometry>
		</visual>
		<visual name="drawer_side-55">
			<origin xyz="0.01855345890418502 -0.4566991883338948 0.41623198986053467"/>
			<geometry>
				<mesh filename="textured_objs/original-33.obj"/>
			</geometry>
		</visual>
		<visual name="drawer_back-56">
			<origin xyz="0.01855345890418502 -0.4566991883338948 0.41623198986053467"/>
			<geometry>
				<mesh filename="textured_objs/original-34.obj"/>
			</geometry>
		</visual>
		<visual name="drawer_bottom-57">
			<origin xyz="0.01855345890418502 -0.4566991883338948 0.41623198986053467"/>
			<geometry>
				<mesh filename="textured_objs/original-32.obj"/>
			</geometry>
		</visual>
		<visual name="drawer_bottom-57">
			<origin xyz="0.01855345890418502 -0.4566991883338948 0.41623198986053467"/>
			<geometry>
				<mesh filename="textured_objs/original-31.obj"/>
			</geometry>
		</visual>
		<visual name="handle-8">
			<origin xyz="0.01855345890418502 -0.4566991883338948 0.41623198986053467"/>
			<geometry>
				<mesh filename="textured_objs/original-50.obj"/>
			</geometry>
		</visual>
		<visual name="handle-8">
			<origin xyz="0.01855345890418502 -0.4566991883338948 0.41623198986053467"/>
			<geometry>
				<mesh filename="textured_objs/original-49.obj"/>
			</geometry>
		</visual>
		<visual name="handle-8">
			<origin xyz="0.01855345890418502 -0.4566991883338948 0.41623198986053467"/>
			<geometry>
				<mesh filename="textured_objs/original-51.obj"/>
			</geometry>
		</visual>
		<visual name="handle-9">
			<origin xyz="0.01855345890418502 -0.4566991883338948 0.41623198986053467"/>
			<geometry>
				<mesh filename="textured_objs/original-54.obj"/>
			</geometry>
		</visual>
		<visual name="handle-9">
			<origin xyz="0.01855345890418502 -0.4566991883338948 0.41623198986053467"/>
			<geometry>
				<mesh filename="textured_objs/original-55.obj"/>
			</geometry>
		</visual>
		<visual name="handle-9">
			<origin xyz="0.01855345890418502 -0.4566991883338948 0.41623198986053467"/>
			<geometry>
				<mesh filename="textured_objs/original-53.obj"/>
			</geometry>
		</visual>
		<collision>
			<origin xyz="0.01855345890418502 -0.4566991883338948 0.41623198986053467"/>
			<geometry>
				<mesh filename="textured_objs/original-29.obj"/>
			</geometry>
		</collision>
		<collision>
			<origin xyz="0.01855345890418502 -0.4566991883338948 0.41623198986053467"/>
			<geometry>
				<mesh filename="textured_objs/original-41.obj"/>
			</geometry>
		</collision>
		<collision>
			<origin xyz="0.01855345890418502 -0.4566991883338948 0.41623198986053467"/>
			<geometry>
				<mesh filename="textured_objs/original-38.obj"/>
			</geometry>
		</collision>
		<collision>
			<origin xyz="0.01855345890418502 -0.4566991883338948 0.41623198986053467"/>
			<geometry>
				<mesh filename="textured_objs/original-37.obj"/>
			</geometry>
		</collision>
		<collision>
			<origin xyz="0.01855345890418502 -0.4566991883338948 0.41623198986053467"/>
			<geometry>
				<mesh filename="textured_objs/original-47.obj"/>
			</geometry>
		</collision>
		<collision>
			<origin xyz="0.01855345890418502 -0.4566991883338948 0.41623198986053467"/>
			<geometry>
				<mesh filename="textured_objs/original-40.obj"/>
			</geometry>
		</collision>
		<collision>
			<origin xyz="0.01855345890418502 -0.4566991883338948 0.41623198986053467"/>
			<geometry>
				<mesh filename="textured_objs/original-43.obj"/>
			</geometry>
		</collision>
		<collision>
			<origin xyz="0.01855345890418502 -0.4566991883338948 0.41623198986053467"/>
			<geometry>
				<mesh filename="textured_objs/original-42.obj"/>
			</geometry>
		</collision>
		<collision>
			<origin xyz="0.01855345890418502 -0.4566991883338948 0.41623198986053467"/>
			<geometry>
				<mesh filename="textured_objs/original-39.obj"/>
			</geometry>
		</collision>
		<collision>
			<origin xyz="0.01855345890418502 -0.4566991883338948 0.41623198986053467"/>
			<geometry>
				<mesh filename="textured_objs/original-44.obj"/>
			</geometry>
		</collision>
		<collision>
			<origin xyz="0.01855345890418502 -0.4566991883338948 0.41623198986053467"/>
			<geometry>
				<mesh filename="textured_objs/original-46.obj"/>
			</geometry>
		</collision>
		<collision>
			<origin xyz="0.01855345890418502 -0.4566991883338948 0.41623198986053467"/>
			<geometry>
				<mesh filename="textured_objs/original-28.obj"/>
			</geometry>
		</collision>
		<collision>
			<origin xyz="0.01855345890418502 -0.4566991883338948 0.41623198986053467"/>
			<geometry>
				<mesh filename="textured_objs/original-35.obj"/>
			</geometry>
		</collision>
		<collision>
			<origin xyz="0.01855345890418502 -0.4566991883338948 0.41623198986053467"/>
			<geometry>
				<mesh filename="textured_objs/original-33.obj"/>
			</geometry>
		</collision>
		<collision>
			<origin xyz="0.01855345890418502 -0.4566991883338948 0.41623198986053467"/>
			<geometry>
				<mesh filename="textured_objs/original-34.obj"/>
			</geometry>
		</collision>
		<collision>
			<origin xyz="0.01855345890418502 -0.4566991883338948 0.41623198986053467"/>
			<geometry>
				<mesh filename="textured_objs/original-32.obj"/>
			</geometry>
		</collision>
		<collision>
			<origin xyz="0.01855345890418502 -0.4566991883338948 0.41623198986053467"/>
			<geometry>
				<mesh filename="textured_objs/original-31.obj"/>
			</geometry>
		</collision>
		<collision>
			<origin xyz="0.01855345890418502 -0.4566991883338948 0.41623198986053467"/>
			<geometry>
				<mesh filename="textured_objs/original-50.obj"/>
			</geometry>
		</collision>
		<collision>
			<origin xyz="0.01855345890418502 -0.4566991883338948 0.41623198986053467"/>
			<geometry>
				<mesh filename="textured_objs/original-49.obj"/>
			</geometry>
		</collision>
		<collision>
			<origin xyz="0.01855345890418502 -0.4566991883338948 0.41623198986053467"/>
			<geometry>
				<mesh filename="textured_objs/original-51.obj"/>
			</geometry>
		</collision>
		<collision>
			<origin xyz="0.01855345890418502 -0.4566991883338948 0.41623198986053467"/>
			<geometry>
				<mesh filename="textured_objs/original-54.obj"/>
			</geometry>
		</collision>
		<collision>
			<origin xyz="0.01855345890418502 -0.4566991883338948 0.41623198986053467"/>
			<geometry>
				<mesh filename="textured_objs/original-55.obj"/>
			</geometry>
		</collision>
		<collision>
			<origin xyz="0.01855345890418502 -0.4566991883338948 0.41623198986053467"/>
			<geometry>
				<mesh filename="textured_objs/original-53.obj"/>
			</geometry>
		</collision>
	</link>
	<joint name="joint_2" type="prismatic">
		<origin xyz="-0.01855345890418502 0.4566991883338948 -0.41623198986053467"/>
		<axis xyz="0 0 1"/>
		<child link="link_2"/>
		<parent link="link_3"/>
		<limit lower="0" upper="0.6080000000000001"/>
	</joint>
	<link name="link_3">
		<visual name="shelf-58">
			<origin xyz="0 0 0"/>
			<geometry>
				<mesh filename="textured_objs/original-17.obj"/>
			</geometry>
		</visual>
		<visual name="other_leaf-27">
			<origin xyz="0 0 0"/>
			<geometry>
				<mesh filename="textured_objs/original-8.obj"/>
			</geometry>
		</visual>
		<visual name="other_leaf-26">
			<origin xyz="0 0 0"/>
			<geometry>
				<mesh filename="textured_objs/original-10.obj"/>
			</geometry>
		</visual>
		<visual name="other_leaf-25">
			<origin xyz="0 0 0"/>
			<geometry>
				<mesh filename="textured_objs/original-9.obj"/>
			</geometry>
		</visual>
		<visual name="other_leaf-24">
			<origin xyz="0 0 0"/>
			<geometry>
				<mesh filename="textured_objs/original-11.obj"/>
			</geometry>
		</visual>
		<visual name="bottom_panel-31">
			<origin xyz="0 0 0"/>
			<geometry>
				<mesh filename="textured_objs/original-16.obj"/>
			</geometry>
		</visual>
		<visual name="vertical_side_panel-32">
			<origin xyz="0 0 0"/>
			<geometry>
				<mesh filename="textured_objs/original-14.obj"/>
			</geometry>
		</visual>
		<visual name="vertical_side_panel-32">
			<origin xyz="0 0 0"/>
			<geometry>
				<mesh filename="textured_objs/original-13.obj"/>
			</geometry>
		</visual>
		<visual name="vertical_side_panel-33">
			<origin xyz="0 0 0"/>
			<geometry>
				<mesh filename="textured_objs/original-20.obj"/>
			</geometry>
		</visual>
		<visual name="vertical_side_panel-33">
			<origin xyz="0 0 0"/>
			<geometry>
				<mesh filename="textured_objs/original-19.obj"/>
			</geometry>
		</visual>
		<visual name="back_panel-34">
			<origin xyz="0 0 0"/>
			<geometry>
				<mesh filename="textured_objs/original-24.obj"/>
			</geometry>
		</visual>
		<visual name="back_panel-34">
			<origin xyz="0 0 0"/>
			<geometry>
				<mesh filename="textured_objs/original-88.obj"/>
			</geometry>
		</visual>
		<visual name="frame_horizontal_bar-36">
			<origin xyz="0 0 0"/>
			<geometry>
				<mesh filename="textured_objs/original-23.obj"/>
			</geometry>
		</visual>
		<visual name="frame_vertical_bar-42">
			<origin xyz="0 0 0"/>
			<geometry>
				<mesh filename="textured_objs/original-4.obj"/>
			</geometry>
		</visual>
		<visual name="frame_vertical_bar-43">
			<origin xyz="0 0 0"/>
			<geometry>
				<mesh filename="textured_objs/original-6.obj"/>
			</geometry>
		</visual>
		<visual name="frame_vertical_bar-44">
			<origin xyz="0 0 0"/>
			<geometry>
				<mesh filename="textured_objs/original-2.obj"/>
			</geometry>
		</visual>
		<visual name="frame_horizontal_bar-45">
			<origin xyz="0 0 0"/>
			<geometry>
				<mesh filename="textured_objs/original-5.obj"/>
			</geometry>
		</visual>
		<visual name="frame_horizontal_bar-46">
			<origin xyz="0 0 0"/>
			<geometry>
				<mesh filename="textured_objs/original-7.obj"/>
			</geometry>
		</visual>
		<visual name="frame_horizontal_bar-47">
			<origin xyz="0 0 0"/>
			<geometry>
				<mesh filename="textured_objs/original-3.obj"/>
			</geometry>
		</visual>
		<visual name="base_side_panel-38">
			<origin xyz="0 0 0"/>
			<geometry>
				<mesh filename="textured_objs/original-22.obj"/>
			</geometry>
		</visual>
		<visual name="base_side_panel-39">
			<origin xyz="0 0 0"/>
			<geometry>
				<mesh filename="textured_objs/original-15.obj"/>
			</geometry>
		</visual>
		<visual name="base_side_panel-40">
			<origin xyz="0 0 0"/>
			<geometry>
				<mesh filename="textured_objs/original-25.obj"/>
			</geometry>
		</visual>
		<visual name="base_side_panel-41">
			<origin xyz="0 0 0"/>
			<geometry>
				<mesh filename="textured_objs/original-21.obj"/>
			</geometry>
		</visual>
		<collision>
			<origin xyz="0 0 0"/>
			<geometry>
				<mesh filename="textured_objs/original-17.obj"/>
			</geometry>
		</collision>
		<collision>
			<origin xyz="0 0 0"/>
			<geometry>
				<mesh filename="textured_objs/original-8.obj"/>
			</geometry>
		</collision>
		<collision>
			<origin xyz="0 0 0"/>
			<geometry>
				<mesh filename="textured_objs/original-10.obj"/>
			</geometry>
		</collision>
		<collision>
			<origin xyz="0 0 0"/>
			<geometry>
				<mesh filename="textured_objs/original-9.obj"/>
			</geometry>
		</collision>
		<collision>
			<origin xyz="0 0 0"/>
			<geometry>
				<mesh filename="textured_objs/original-11.obj"/>
			</geometry>
		</collision>
		<collision>
			<origin xyz="0 0 0"/>
			<geometry>
				<mesh filename="textured_objs/original-16.obj"/>
			</geometry>
		</collision>
		<collision>
			<origin xyz="0 0 0"/>
			<geometry>
				<mesh filename="textured_objs/original-14.obj"/>
			</geometry>
		</collision>
		<collision>
			<origin xyz="0 0 0"/>
			<geometry>
				<mesh filename="textured_objs/original-13.obj"/>
			</geometry>
		</collision>
		<collision>
			<origin xyz="0 0 0"/>
			<geometry>
				<mesh filename="textured_objs/original-20.obj"/>
			</geometry>
		</collision>
		<collision>
			<origin xyz="0 0 0"/>
			<geometry>
				<mesh filename="textured_objs/original-19.obj"/>
			</geometry>
		</collision>
		<collision>
			<origin xyz="0 0 0"/>
			<geometry>
				<mesh filename="textured_objs/original-24.obj"/>
			</geometry>
		</collision>
		<collision>
			<origin xyz="0 0 0"/>
			<geometry>
				<mesh filename="textured_objs/original-88.obj"/>
			</geometry>
		</collision>
		<collision>
			<origin xyz="0 0 0"/>
			<geometry>
				<mesh filename="textured_objs/original-23.obj"/>
			</geometry>
		</collision>
		<collision>
			<origin xyz="0 0 0"/>
			<geometry>
				<mesh filename="textured_objs/original-4.obj"/>
			</geometry>
		</collision>
		<collision>
			<origin xyz="0 0 0"/>
			<geometry>
				<mesh filename="textured_objs/original-6.obj"/>
			</geometry>
		</collision>
		<collision>
			<origin xyz="0 0 0"/>
			<geometry>
				<mesh filename="textured_objs/original-2.obj"/>
			</geometry>
		</collision>
		<collision>
			<origin xyz="0 0 0"/>
			<geometry>
				<mesh filename="textured_objs/original-5.obj"/>
			</geometry>
		</collision>
		<collision>
			<origin xyz="0 0 0"/>
			<geometry>
				<mesh filename="textured_objs/original-7.obj"/>
			</geometry>
		</collision>
		<collision>
			<origin xyz="0 0 0"/>
			<geometry>
				<mesh filename="textured_objs/original-3.obj"/>
			</geometry>
		</collision>
		<collision>
			<origin xyz="0 0 0"/>
			<geometry>
				<mesh filename="textured_objs/original-22.obj"/>
			</geometry>
		</collision>
		<collision>
			<origin xyz="0 0 0"/>
			<geometry>
				<mesh filename="textured_objs/original-15.obj"/>
			</geometry>
		</collision>
		<collision>
			<origin xyz="0 0 0"/>
			<geometry>
				<mesh filename="textured_objs/original-25.obj"/>
			</geometry>
		</collision>
		<collision>
			<origin xyz="0 0 0"/>
			<geometry>
				<mesh filename="textured_objs/original-21.obj"/>
			</geometry>
		</collision>
	</link>
	<joint name="joint_3" type="fixed">
		<origin rpy="1.570796326794897 0 -1.570796326794897" xyz="0 0 0"/>
		<child link="link_3"/>
		<parent link="base"/>
	</joint>
</robot>
